Workbook

Sheet Summary
A1: Year | B1: Meat | C1: Participant | D1: Score | E1: Rank | F1: Location
A2: 2019 | B2: ='2019'!B5 -> Chicken | C2: ='2019'!C5 -> Sudheer | D2: ='2019'!D5 -> 158.8344 | E2: ='2019'!E5 -> 33 | F2: Smoke on the Trails
A3: 2019 | B3: ='2019'!B6 -> Ribs | C3: ='2019'!C6 -> Kendall | D3: ='2019'!D6 -> 159.9428 | E3: ='2019'!E6 -> 32 | F3: Smoke on the Trails
A4: 2019 | B4: ='2019'!B7 -> Pork | C4: ='2019'!C7 -> Tan | D4: ='2019'!D7 -> 165.7028 | E4: ='2019'!E7 -> 19 | F4: Smoke on the Trails
A5: 2019 | B5: ='2019'!B8 -> Brisket | C5: ='2019'!C8 -> Andy | D5: ='2019'!D8 -> 146.8 | E5: ='2019'!E8 -> 44 | F5: Smoke on the Trails
A6: 2020 | B6: ='2020'!B5 -> Chicken | C6: ='2020'!C5 -> Sudheer | D6: ='2020'!D5 -> 158.2744 | E6: ='2020'!E5 -> 39 | F6: Smoke on the Trails
A7: 2020 | B7: ='2020'!B6 -> Ribs | C7: ='2020'!C6 -> Andy | D7: ='2020'!D6 -> 154.8116 | E7: ='2020'!E6 -> 39 | F7: Smoke on the Trails
A8: 2020 | B8: ='2020'!B7 -> Pork | C8: ='2020'!C7 -> Tan | D8: ='2020'!D7 -> 161.0856 | E8: ='2020'!E7 -> 38 | F8: Smoke on the Trails
A9: 2020 | B9: ='2020'!B8 -> Brisket | C9: ='2020'!C8 -> Andy | D9: ='2020'!D8 -> 153.12 | E9: ='2020'!E8 -> 40 | F9: Smoke on the Trails
A10: 2021 | B10: ='2021'!B5 -> Chicken | C10: ='2021'!C5 -> Sudheer | D10: ='2021'!D5 -> 158.8116 | E10: ='2021'!E5 -> 21 | F10: Smoke on the Trails
A11: 2021 | B11: ='2021'!B6 -> Ribs | C11: ='2021'!C6 -> Grant | D11: ='2021'!D6 -> 163.9428 | E11: ='2021'!E6 -> 33 | F11: Smoke on the Trails
A12: 2021 | B12: ='2021'!B7 -> Pork | C12: ='2021'!C7 -> Tan | D12: ='2021'!D7 -> 170.8228 | E12: ='2021'!E7 -> 27 | F12: Smoke on the Trails
A13: 2021 | B13: ='2021'!B8 -> Brisket | C13: ='2021'!C8 -> Andy | D13: ='2021'!D8 -> 170.2628 | E13: ='2021'!E8 -> 41 | F13: Smoke on the Trails
A14: 2021 | B14: ='2021'!B17 -> Chicken | C14: ='2021'!C17 -> Sudheer | D14: ='2021'!D17 -> 159.9656 | E14: ='2021'!E17 -> 94 | F14: The Great Lenexa BBQ-Battle Kansas State Championship
A15: 2021 | B15: ='2021'!B18 -> Ribs | C15: ='2021'!C18 -> Grant | D15: ='2021'!D18 -> 141.6572 | E15: ='2021'!E18 -> 139 | F15: The Great Lenexa BBQ-Battle Kansas State Championship
A16: 2021 | B16: ='2021'!B19 -> Pork | C16: ='2021'!C19 -> Tan | D16: ='2021'!D19 -> 160 | E16: ='2021'!E19 -> 89 | F16: The Great Lenexa BBQ-Battle Kansas State Championship
A17: 2021 | B17: ='2021'!B20 -> Brisket | C17: ='2021'!C20 -> Andy | D17: ='2021'!D20 -> 167.4172 | E17: ='2021'!E20 -> 35 | F17: The Great Lenexa BBQ-Battle Kansas State Championship
A18: 2022 | B18: ='2022'!B5 -> Chicken | C18: ='2022'!C5 -> Sudheer | D18: ='2022'!D5 -> 173.12 | E18: ='2022'!E5 -> 10 | F18: Smoke on the Trails
A19: 2022 | B19: ='2022'!B6 -> Ribs | C19: ='2022'!C6 -> Tan | D19: ='2022'!D6 -> 166.2744 | E19: ='2022'!E6 -> 20 | F19: Smoke on the Trails
A20: 2022 | B20: ='2022'!B7 -> Pork | C20: ='2022'!C7 -> Tan | D20: ='2022'!D7 -> 159.4056 | E20: ='2022'!E7 -> 32 | F20: Smoke on the Trails
A21: 2022 | B21: ='2022'!B8 -> Brisket | C21: ='2022'!C8 -> Andy | D21: ='2022'!D8 -> 160.5028 | E21: ='2022'!E8 -> 26 | F21: Smoke on the Trails
A22: 2022 | B22: ='2022'!B16 -> Chicken | C22: ='2022'!C16 -> Eric | D22: ='2022'!D16 -> 166.88 | E22: ='2022'!E16 -> 51 | F22: The Great Lenexa BBQ-Battle Kansas State Championship
A23: 2022 | B23: ='2022'!B17 -> Ribs | C23: ='2022'!C17 -> Brad | D23: ='2022'!D17 -> 153.7144 | E23: ='2022'!E17 -> 134 | F23: The Great Lenexa BBQ-Battle Kansas State Championship
A24: 2022 | B24: ='2022'!B18 -> Pork | C24: ='2022'!C18 -> Mike | D24: ='2022'!D18 -> 156.5256 | E24: ='2022'!E18 -> 130 | F24: The Great Lenexa BBQ-Battle Kansas State Championship
A25: 2022 | B25: ='2022'!B19 -> Brisket | C25: ='2022'!C19 -> Andy | D25: ='2022'!D19 -> 172.64 | E25: ='2022'!E19 -> 13 | F25: The Great Lenexa BBQ-Battle Kansas State Championship
A26: 2023 | B26: ='2023'!B5 -> Chicken | C26: ='2023'!C5 -> Sudheer | D26: ='2023'!D5 -> 168.5372 | E26: ='2023'!E5 -> 25 | F26: Smoke on the Trails
A27: 2023 | B27: ='2023'!B6 -> Ribs | C27: ='2023'!C6 -> Grant | D27: ='2023'!D6 -> 151.92 | E27: ='2023'!E6 -> 36 | F27: Smoke on the Trails
A28: 2023 | B28: ='2023'!B7 -> Pork | C28: ='2023'!C7 -> Tan | D28: ='2023'!D7 -> 162.8 | E28: ='2023'!E7 -> 28 | F28: Smoke on the Trails
A29: 2023 | B29: ='2023'!B8 -> Brisket | C29: ='2023'!C8 -> Andy | D29: ='2023'!D8 -> 162.2628 | E29: ='2023'!E8 -> 22 | F29: Smoke on the Trails
A30: 2023 | B30: ='2023'!B16 -> Chicken | C30: ='2023'!C16 -> Sudheer | D30: ='2023'!D16 -> 159.3828 | E30: ='2023'!E16 -> 117 | F30: The Great Lenexa BBQ-Battle Kansas State Championship
A31: 2023 | B31: ='2023'!B17 -> Ribs | C31: ='2023'!C17 -> Grant | D31: ='2023'!D17 -> 169.7144 | E31: ='2023'!E17 -> 42 | F31: The Great Lenexa BBQ-Battle Kansas State Championship
A32: 2023 | B32: ='2023'!B18 -> Pork | C32: ='2023'!C18 -> James | D32: ='2023'!D18 -> 161.0972 | E32: ='2023'!E18 -> 113 | F32: The Great Lenexa BBQ-Battle Kansas State Championship
A33: 2023 | B33: ='2023'!B19 -> Brisket | C33: ='2023'!C19 -> Andy | D33: ='2023'!D19 -> 167.9656 | E33: ='2023'!E19 -> 38 | F33: The Great Lenexa BBQ-Battle Kansas State Championship
A34: 2024 | B34: ='2024'!B5 -> Chicken | C34: ='2024'!C5 -> Sudheer | D34: ='2024'!D5 -> 161.1428 | E34: ='2024'!E5 -> 98 | F34: The Great Lenexa BBQ-Battle Kansas State Championship
A35: 2024 | B35: ='2024'!B6 -> Ribs | C35: ='2024'!C6 -> Grant | D35: ='2024'!D6 -> 159.3828 | E35: ='2024'!E6 -> 111 | F35: The Great Lenexa BBQ-Battle Kansas State Championship
A36: 2024 | B36: ='2024'!B7 -> Pork | C36: ='2024'!C7 -> Tan | D36: ='2024'!D7 -> 169.7028 | E36: ='2024'!E7 -> 42 | F36: The Great Lenexa BBQ-Battle Kansas State Championship
A37: 2024 | B37: ='2024'!B8 -> Brisket | C37: ='2024'!C8 -> Andy | D37: ='2024'!D8 -> 174.2972 | E37: ='2024'!E8 -> 7 | F37: The Great Lenexa BBQ-Battle Kansas State Championship
A38: 2024 | B38: ='2024'!B17 -> Chicken | C38: ='2024'!C17 -> Jack | D38: ='2024'!D17 -> 154.8228 | E38: ='2024'!E17 -> 41 | F38: Smoke on the Bricks
A39: 2024 | B39: ='2024'!B18 -> Ribs | C39: ='2024'!C18 -> Grant | D39: ='2024'!D18 -> 157.0628 | E39: ='2024'!E18 -> 39 | F39: Smoke on the Bricks
A40: 2024 | B40: ='2024'!B19 -> Pork | C40: ='2024'!C19 -> Tan | D40: ='2024'!D19 -> 173.12 | E40: ='2024'!E19 -> 16 | F40: Smoke on the Bricks
...

Sheet Pivot Table 1

Sheet 2019
B1: Competition | C1: Smoke on the Trails
B2: Total Teams | C2: 53
B4: Meat | C4: Member | D4: Score | E4: Rank
B5: Chicken | C5: Sudheer | D5: 158.8344 | E5: 33
B6: Ribs | C6: Kendall | D6: 159.9428 | E6: 32
B7: Pork | C7: Tan | D7: 165.7028 | E7: 19
B8: Brisket | C8: Andy | D8: 146.8 | E8: 44
A9: Team Totals | D9: =SUM(D5:D8) -> 631.28 | E9: 34

Sheet 2020
B1: Competition | C1: Smoke on the Trails
B2: Total Teams | C2: 48
B4: Meat | C4: Member | D4: Score | E4: Rank
B5: Chicken | C5: Sudheer | D5: 158.2744 | E5: 39
B6: Ribs | C6: Andy | D6: 154.8116 | E6: 39
B7: Pork | C7: Tan | D7: 161.0856 | E7: 38
B8: Brisket | C8: Andy | D8: 153.12 | E8: 40
A9: Team Totals | D9: =SUM(D5:D8) -> 627.2916 | E9: 41

Sheet 2021
B1: Competition | C1: Smoke on the Trails
B2: Total Teams | C2: 53
B4: Meat | C4: Member | D4: Score | E4: Rank
B5: Chicken | C5: Sudheer | D5: 158.8116 | E5: 21
B6: Ribs | C6: Grant | D6: 163.9428 | E6: 33
B7: Pork | C7: Tan | D7: 170.8228 | E7: 27
B8: Brisket | C8: Andy | D8: 170.2628 | E8: 41
A9: Team Totals | D9: =SUM(D5:D8) -> 663.84 | E9: 30
B10: Desert | C10: Sudheer | D10: 166.2628 | E10: 8 / 11
B13: Competition | C13: The Great Lenexa BBQ-Battle Kansas State Championship
B14: Total Teams | C14: 145
B16: Meat | C16: Member | D16: Score | E16: Rank
B17: Chicken | C17: Sudheer | D17: 159.9656 | E17: 94
B18: Ribs | C18: Grant | D18: 141.6572 | E18: 139
B19: Pork | C19: Tan | D19: 160 | E19: 89
B20: Brisket | C20: Andy | D20: 167.4172 | E20: 35
A21: Team Totals | D21: =SUM(D17:D20) -> 629.04 | E21: 100

Sheet 2022
B1: Competition | C1: Smoke on the Trails
B2: Total Teams | C2: 37
B4: Meat | C4: Member | D4: Score | E4: Rank | F4: Out of
B5: Chicken | C5: Sudheer | D5: 173.12 | E5: 10
B6: Ribs | C6: Tan | D6: 166.2744 | E6: 20
B7: Pork | C7: Tan | D7: 159.4056 | E7: 32
B8: Brisket | C8: Andy | D8: 160.5028 | E8: 26
A9: Team Totals | D9: =SUM(D5:D8) -> 659.3028 | E9: 22
B12: Competition | C12: The Great Lenexa BBQ-Battle Kansas State Championship
B13: Total Teams | C13: 164
B15: Meat | C15: Member | D15: Score | E15: Rank
B16: Chicken | C16: Eric | D16: 166.88 | E16: 51
B17: Ribs | C17: Brad | D17: 153.7144 | E17: 134
B18: Pork | C18: Mike | D18: 156.5256 | E18: 130
B19: Brisket | C19: Andy | D19: 172.64 | E19: 13
A20: Team Totals | D20: =SUM(D16:D19) -> 649.76 | E20: 85
B21: Beefsteak | D21: 157.7256 | E21: 55 / 74
B22: Sausage | D22: 164.56 | E22: 61 / 120

Sheet 2023
B1: Competition | C1: Smoke on the Trails
B2: Total Teams | C2: 38
B4: Meat | C4: Member | D4: Score | E4: Rank | F4: Out of
B5: Chicken | C5: Sudheer | D5: 168.5372 | E5: 25
B6: Ribs | C6: Grant | D6: 151.92 | E6: 36
B7: Pork | C7: Tan | D7: 162.8 | E7: 28
B8: Brisket | C8: Andy | D8: 162.2628 | E8: 22
A9: Team Totals | D9: =SUM(D5:D8) -> 645.52 | E9: 29
B10: Desert | C10: Grant | D10: 169.7028 | E10: 45608
B12: Competition | C12: The Great Lenexa BBQ-Battle Kansas State Championship
B13: Total Teams | C13: 167
B15: Meat | C15: Member | D15: Score | E15: Rank
B16: Chicken | C16: Sudheer | D16: 159.3828 | E16: 117
B17: Ribs | C17: Grant | D17: 169.7144 | E17: 42
B18: Pork | C18: James | D18: 161.0972 | E18: 113
B19: Brisket | C19: Andy | D19: 167.9656 | E19: 38
A20: Team Totals | D20: =SUM(D16:D19) -> 658.16 | E20: 63
B21: Beefsteak | D21: 165.7144 | E21: 32 / 60

Sheet 2024
B1: Competition | C1: The Great Lenexa BBQ-Battle Kansas State Championship
B2: Total Teams | C2: 172
B4: Meat | C4: Member | D4: Score | E4: Rank
B5: Chicken | C5: Sudheer | D5: 161.1428 | E5: 98
B6: Ribs | C6: Grant | D6: 159.3828 | E6: 111
B7: Pork | C7: Tan | D7: 169.7028 | E7: 42
B8: Brisket | C8: Andy | D8: 174.2972 | E8: 7
A9: Team Totals | D9: =SUM(D5:D8) -> 664.5256 | E9: 56
B10: Desert | C10: Grant | D10: 166.8228 | E10: 39 / 77
B13: Competition | C13: Smoke on the Bricks
B14: Total Teams | C14: 46
B16: Meat | C16: Member | D16: Score | E16: Rank
B17: Chicken | C17: Jack | D17: 154.8228 | E17: 41
B18: Ribs | C18: Grant | D18: 157.0628 | E18: 39
B19: Pork | C19: Tan | D19: 173.12 | E19: 16
B20: Brisket | C20: Andy | D20: 172 | E20: 12
A21: Team Totals | D21: =SUM(D17:D20) -> 657.0056 | E21: 33
B22: Desert | C22: Amy | D22: 176.56 | E22: 6 / 14
B23: Sausage | C23: James | D23: 160.56 | E23: 20 / 22
B28: Competition | C28: American Royal Open
B29: Total Teams | C29: 444
B31: Meat | C31: Member | D31: Score | E31: Rank
B32: Chicken | C32: Sudheer | D32: 166.8228 | E32: 278
B33: Ribs | C33: Grant | D33: 160.5256 | E33: 373
B34: Pork | C34: James | D34: 165.7028 | E34: 281
B35: Brisket | C35: Andy | D35: 166.2628 | E35: 244
A36: Team Totals | B36: Team Totals | D36: =SUM(D32:D35) -> 659.314 | E36: 316
B37: Sides | C37: Member | D37: Score | E37: Rank
B38: Turkey | D38: 165.1084 | E38: 181 / 235
B39: Sausage | D39: 167.4056 | E39: 131 / 266
B40: Veggies | D40: 173.7028 | E40: 39 / 169
B41: Beans | D41: 161.7028 | E41: 177 / 209
B42: Potato | D42: 154.2172 | E42: 170 / 176
B43: Team Score and Rank (sides) | D43: =SUM(D40:D42) -> 489.6228 | E43: 132

Sheet 2025
B1: Competition | C1: The Great Lenexa BBQ-Battle Kansas State Championship
B2: Total Teams | C2: 159
B4: Meat | C4: Member | D4: Score | E4: Rank
B5: Chicken | C5: Sudheer | D5: 152 | E5: 148
B6: Ribs | C6: Grant | D6: 157.0972 | E6: 124
B7: Pork | C7: Tan | D7: 169.7028 | E7: 48
B8: Brisket | C8: Andy | D8: 173.7028 | E8: 15
A9: Team Totals | D9: =SUM(D5:D8) -> 652.5028 | E9: 89
B10: Sausage | C10: Grant | D10: 174.2856 | E10: 10/113
B11: Beefsteak | C11: Andy | D11: 180 | E11: 1/67
B12: Misc | C12: Tan | D12: 173.1656 | E12: 15/73
B14: Competition | C14: Smoke on the Bricks
B15: Total Teams | C15: 53
B17: Meat | C17: Member | D17: Score | E17: Rank
B18: Chicken | C18: James | D18: 172 | E18: 29
B19: Ribs | C19: Grant | D19: 166.8228 | E19: 38
B20: Pork | C20: Tan | D20: 165.6684 | E20: 42
B21: Brisket | C21: Andy | D21: 169.68 | E21: 29
A22: Team Totals | D22: =SUM(D18:D21) -> 674.1712 | E22: 33
B23: Sausage | C23: Grant | D23: 162.7884 | E23: 21/22
B25: Competition | C25: Meat Inferno
B26: Total Teams | C26: 21
B28: Meat | C28: Member | D28: Score | E28: Rank
B29: Chicken | C29: Sudheer | D29: 169.7144 | E29: 9
B30: Ribs | C30: Grant | D30: 166.24 | E30: 15
B31: Pork | C31: Tan | D31: 162.8228 | E31: 18
B32: Brisket | C32: Andy | D32: 174.2744 | E32: 5
A33: Team Totals | D33: =SUM(D29:D32) -> 673.0516 | E33: 14
B35: Competition | C35: American Royal Open
B36: Total Teams | C36: 401
B37: High Score | C37: 708.5488
B38: Meat | C38: Member | D38: Score | E38: Rank
B39: Chicken | C39: Sudheer | D39: 173.7144 | E39: 112
B40: Ribs | C40: Grant | D40: 174.8456 | E40: 71
B41: Pork | C41: Tan | D41: 165.0856 | E41: 293
B42: Brisket | C42: Andy | D42: 165.1084 | E42: 254
A43: Team Totals | D43: =SUM(D39:D42) -> 678.754 | E43: 193
B44: Turkey | C44: Tan | D44: 173.1656 | E44: 55 / 223
B45: Sausage | C45: Grant | D45: 171.4172 | E45: 82 / 242
B46: Veggies | C46: Sudheer | D46: 170.8572 | E46: 77 / 173
...
